Workbook

Sheet Bilgi
A1: Kahve Durağı — Defter Çalışma Kitabı
A2: KURGUSAL İŞLETME · Muhasebe 101 lab'ı · Bu çalışma kitabı eğitim amaçlıdır. Mali müşavirlik hizmeti değildir. Kendi durumunuz için mali müşavirinize danışın.
A4: Unvan | B4: Kahve Durağı Ltd. Şti. (KURGUSAL)
A5: Faaliyet | B5: kahve demleme ekipmanı satan küçük dükkân ve çevrim içi satış (kurgusal)
A6: Vergi kimlik no | B6: 0000000000
A7: Adres | B7: Örnek Mah. Deneme Sok. No: 0, Eskişehir (kurgusal)
A8: Telefon | B8: 0222 000 00 00
A9: E-posta | B9: defter@example.com
A10: Defter esası | B10: bilanço esası — her türlü ticaret şirketi I. sınıf tüccardır (VUK md. 177/4)
A11: Dönem | B11: Ocak 2026 (ara dönem, öğrenme amaçlı)
A13: Parametreler (formüller buradan okur)
A14: Parametre | B14: Değer | C14: Kaynak / not
A15: KDV genel oranı | B15: 0.2 | C15: 2007/13033 sayılı BKK md. 1/(a), 7346 sayılı Cumhurbaşkanı Kararı ile %18 → %20 (RG 7.7.2023, sayı 32241); GİB mevzuat sayfasında KDV oran kararlarının sonuncusu 9126 (RG 14.11.2024, yalnız liste değişikliği) — okundu 2026-09-25 · Kahve Durağı'nın bütün alış/satışlarında genel oran uygulandığı VARSAYILDI; bir ürünün (I) ya da (II) sayılı listede olup olmadığı ders kapsamında belirlenmez
A16: Doğrudan gider yazma haddi (2026) | B16: 12000 | C16: VUK md. 313; 588 Sıra No.lu VUK Genel Tebliği ile 1.1.2026'dan geçerli tutar (RG 30.12.2025, sayı 33124 5. mükerrer) — mevzuat.gov.tr VUK metni, okundu 2026-09-25
A17: Tezgâh ve raf sistemi faydalı ömrü (ÖRNEK) | B17: 5 | C17: ÖRNEK — Hazine ve Maliye Bakanlığı amortisman listesindeki karşılığı bu kayıtta doğrulanmadı (ACIK-SORULAR Q7)
A19: Sayfalar
A20: Hesap Planı | B20: kullanılan hesaplar — Tekdüzen Hesap Planı kodlarıyla (MSUGT, RG 26.12.1992)
A21: Yevmiye | B21: tarih sırasıyla maddeler; her madde borç = alacak
A22: Büyük Defter | B22: yevmiyedeki satırların hesap hesap dağılımı ve bakiyesi
A23: Mizan | B23: hesapların borç/alacak toplamları ve kalanları; denklik kontrolü
A24: Banka Ekstresi | B24: bankanın belgesi (kurgusal) ve defterle mutabakat
A25: KDV | B25: hesaplanan, indirilecek, ödenecek / devreden KDV
A26: Stok | B26: ay sonu sayım → satılan malın maliyeti
A27: Amortisman | B27: demirbaşın yıllara dağıtılması; doğrudan gider haddi
A28: Gelir Tablosu | B28: dönemin kârı — mizandan formülle
A29: Bilanço | B29: ay sonu varlıklar = kaynaklar — mizandan formülle
A30: Takvim | B30: 2026 vergi takvimi örnekleri (GİB, okundu 2026-09-25)

Sheet Hesap Planı
A1: Hesap Planı (kullanılan hesaplar)
A2: Kodlar Tekdüzen Hesap Planı'ndan (Muhasebe Sistemi Uygulama Genel Tebliği Sıra No: 1, RG 26.12.1992 sayı 21447 mük.). Ticaret işletmesi olarak giderler 7/B seçeneğiyle (79 Gider Çeşitleri) izlenir.
A4: Kod | B4: Hesap adı | C4: Grup | D4: Tür | E4: Normal bakiye
A5: 100 | B5: Kasa | C5: 1 Dönen Varlıklar | D5: Varlık | E5: Borç
A6: 102 | B6: Bankalar | C6: 1 Dönen Varlıklar | D6: Varlık | E6: Borç
A7: 120 | B7: Alıcılar | C7: 1 Dönen Varlıklar | D7: Varlık | E7: Borç
A8: 153 | B8: Ticari Mallar | C8: 1 Dönen Varlıklar | D8: Varlık | E8: Borç
A9: 191 | B9: İndirilecek KDV | C9: 1 Dönen Varlıklar | D9: Varlık | E9: Borç
A10: 255 | B10: Demirbaşlar | C10: 2 Duran Varlıklar | D10: Varlık | E10: Borç
A11: 257 | B11: Birikmiş Amortismanlar (-) | C11: 2 Duran Varlıklar | D11: Varlık (düzenleyici) | E11: Alacak
A12: 320 | B12: Satıcılar | C12: 3 Kısa Vadeli Yabancı Kaynaklar | D12: Kaynak | E12: Alacak
A13: 360 | B13: Ödenecek Vergi ve Fonlar | C13: 3 Kısa Vadeli Yabancı Kaynaklar | D13: Kaynak | E13: Alacak
A14: 391 | B14: Hesaplanan KDV | C14: 3 Kısa Vadeli Yabancı Kaynaklar | D14: Kaynak | E14: Alacak
A15: 500 | B15: Sermaye | C15: 5 Öz Kaynaklar | D15: Kaynak | E15: Alacak
A16: 600 | B16: Yurt İçi Satışlar | C16: 6 Gelir Tablosu Hesapları | D16: Gelir | E16: Alacak
... A22: 798 | B22: Gider Çeşitleri Yansıtma Hesabı | C22: 7 Maliyet Hesapları (7/B) | D22: Yansıtma | E22: Alacak

Sheet Yevmiye
A1: Yevmiye Defteri — Ocak 2026
A2: Her madde bir belgeye dayanır; bir maddenin borç toplamı alacak toplamına eşit olmalıdır (I sütunu).
A4: Madde | B4: Tarih | C4: Belge | D4: Açıklama | E4: Hesap | F4: Hesap adı | G4: Borç | H4: Alacak | I4: Madde kontrolü
A5: 1 | B5: 46024 | C5: Banka dekontu ÖRN-D-001 | D5: Ortakların sermaye ödemesi bankaya yatırıldı | E5: 102 | F5: =IFERROR(VLOOKUP(E5,'Hesap Planı'!$A$5:$B$22,2,FALSE),"HESAP PLANINDA YOK") | G5: 300000 | I5: =IF(ROUND(SUMIF($A$5:$A$200,A5,$G$5:$G$200)-SUMIF($A$5:$A$200,A5,$H$5:$H$200),2)=0,"DENK","DENK DEĞİL")
A6: 1 | B6: 46024 | C6: Banka dekontu ÖRN-D-001 | D6: Ortakların sermaye ödemesi bankaya yatırıldı | E6: 500 | F6: =IFERROR(VLOOKUP(E6,'Hesap Planı'!$A$5:$B$22,2,FALSE),"HESAP PLANINDA YOK") | H6: 300000
A7: 2 | B7: 46025 | C7: Banka dekontu ÖRN-D-002 | D7: Bankadan kasaya para çekildi | E7: 100 | F7: =IFERROR(VLOOKUP(E7,'Hesap Planı'!$A$5:$B$22,2,FALSE),"HESAP PLANINDA YOK") | G7: 20000 | I7: =IF(ROUND(SUMIF($A$5:$A$200,A7,$G$5:$G$200)-SUMIF($A$5:$A$200,A7,$H$5:$H$200),2)=0,"DENK","DENK DEĞİL")
A8: 2 | B8: 46025 | C8: Banka dekontu ÖRN-D-002 | D8: Bankadan kasaya para çekildi | E8: 102 | F8: =IFERROR(VLOOKUP(E8,'Hesap Planı'!$A$5:$B$22,2,FALSE),"HESAP PLANINDA YOK") | H8: 20000
A9: 3 | B9: 46028 | C9: Alış e-Faturası ÖRN-A-001 | D9: Tezgâh ve raf sistemi alındı (demirbaş) | E9: 255 | F9: =IFERROR(VLOOKUP(E9,'Hesap Planı'!$A$5:$B$22,2,FALSE),"HESAP PLANINDA YOK") | G9: 90000 | I9: =IF(ROUND(SUMIF($A$5:$A$200,A9,$G$5:$G$200)-SUMIF($A$5:$A$200,A9,$H$5:$H$200),2)=0,"DENK","DENK DEĞİL")
A10: 3 | B10: 46028 | C10: Alış e-Faturası ÖRN-A-001 | D10: Tezgâh ve raf sistemi alındı (demirbaş) | E10: 191 | F10: =IFERROR(VLOOKUP(E10,'Hesap Planı'!$A$5:$B$22,2,FALSE),"HESAP PLANINDA YOK") | G10: 18000
A11: 3 | B11: 46028 | C11: Alış e-Faturası ÖRN-A-001 | D11: Tezgâh ve raf sistemi alındı (demirbaş) | E11: 102 | F11: =IFERROR(VLOOKUP(E11,'Hesap Planı'!$A$5:$B$22,2,FALSE),"HESAP PLANINDA YOK") | H11: 108000
A12: 4 | B12: 46028 | C12: Alış faturası ÖRN-A-002 | D12: Barkod okuyucu alındı — doğrudan gider (had altında) | E12: 794 | F12: =IFERROR(VLOOKUP(E12,'Hesap Planı'!$A$5:$B$22,2,FALSE),"HESAP PLANINDA YOK") | G12: 8000 | I12: =IF(ROUND(SUMIF($A$5:$A$200,A12,$G$5:$G$200)-SUMIF($A$5:$A$200,A12,$H$5:$H$200),2)=0,"DENK","DENK DEĞİL")
A13: 4 | B13: 46028 | C13: Alış faturası ÖRN-A-002 | D13: Barkod okuyucu alındı — doğrudan gider (had altında) | E13: 191 | F13: =IFERROR(VLOOKUP(E13,'Hesap Planı'!$A$5:$B$22,2,FALSE),"HESAP PLANINDA YOK") | G13: 1600
A14: 4 | B14: 46028 | C14: Alış faturası ÖRN-A-002 | D14: Barkod okuyucu alındı — doğrudan gider (had altında) | E14: 100 | F14: =IFERROR(VLOOKUP(E14,'Hesap Planı'!$A$5:$B$22,2,FALSE),"HESAP PLANINDA YOK") | H14: 9600
A15: 5 | B15: 46032 | C15: Alış e-Faturası ÖRN-A-003 | D15: Satılmak üzere demleme ekipmanı alındı (vadeli) | E15: 153 | F15: =IFERROR(VLOOKUP(E15,'Hesap Planı'!$A$5:$B$22,2,FALSE),"HESAP PLANINDA YOK") | G15: 150000 | I15: =IF(ROUND(SUMIF($A$5:$A$200,A15,$G$5:$G$200)-SUMIF($A$5:$A$200,A15,$H$5:$H$200),2)=0,"DENK","DENK DEĞİL")
A16: 5 | B16: 46032 | C16: Alış e-Faturası ÖRN-A-003 | D16: Satılmak üzere demleme ekipmanı alındı (vadeli) | E16: 191 | F16: =IFERROR(VLOOKUP(E16,'Hesap Planı'!$A$5:$B$22,2,FALSE),"HESAP PLANINDA YOK") | G16: 30000
A17: 5 | B17: 46032 | C17: Alış e-Faturası ÖRN-A-003 | D17: Satılmak üzere demleme ekipmanı alındı (vadeli) | E17: 320 | F17: =IFERROR(VLOOKUP(E17,'Hesap Planı'!$A$5:$B$22,2,FALSE),"HESAP PLANINDA YOK") | H17: 180000
A18: 6 | B18: 46037 | C18: e-Arşiv faturalar ÖRN-S-001…040 | D18: Bireysel müşterilere satışlar (kartla tahsil) | E18: 102 | F18: =IFERROR(VLOOKUP(E18,'Hesap Planı'!$A$5:$B$22,2,FALSE),"HESAP PLANINDA YOK") | G18: 72000 | I18: =IF(ROUND(SUMIF($A$5:$A$200,A18,$G$5:$G$200)-SUMIF($A$5:$A$200,A18,$H$5:$H$200),2)=0,"DENK","DENK DEĞİL")
A19: 6 | B19: 46037 | C19: e-Arşiv faturalar ÖRN-S-001…040 | D19: Bireysel müşterilere satışlar (kartla tahsil) | E19: 600 | F19: =IFERROR(VLOOKUP(E19,'Hesap Planı'!$A$5:$B$22,2,FALSE),"HESAP PLANINDA YOK") | H19: 60000
A20: 6 | B20: 46037 | C20: e-Arşiv faturalar ÖRN-S-001…040 | D20: Bireysel müşterilere satışlar (kartla tahsil) | E20: 391 | F20: =IFERROR(VLOOKUP(E20,'Hesap Planı'!$A$5:$B$22,2,FALSE),"HESAP PLANINDA YOK") | H20: 12000
A21: 7 | B21: 46042 | C21: Satış e-Faturası ÖRN-S-041 | D21: Örnek Kafe Ltd.'ye vadeli satış (kurgusal müşteri) | E21: 120 | F21: =IFERROR(VLOOKUP(E21,'Hesap Planı'!$A$5:$B$22,2,FALSE),"HESAP PLANINDA YOK") | G21: 48000 | I21: =IF(ROUND(SUMIF($A$5:$A$200,A21,$G$5:$G$200)-SUMIF($A$5:$A$200,A21,$H$5:$H$200),2)=0,"DENK","DENK DEĞİL")
A22: 7 | B22: 46042 | C22: Satış e-Faturası ÖRN-S-041 | D22: Örnek Kafe Ltd.'ye vadeli satış (kurgusal müşteri) | E22: 600 | F22: =IFERROR(VLOOKUP(E22,'Hesap Planı'!$A$5:$B$22,2,FALSE),"HESAP PLANINDA YOK") | H22: 40000
A23: 7 | B23: 46042 | C23: Satış e-Faturası ÖRN-S-041 | D23: Örnek Kafe Ltd.'ye vadeli satış (kurgusal müşteri) | E23: 391 | F23: =IFERROR(VLOOKUP(E23,'Hesap Planı'!$A$5:$B$22,2,FALSE),"HESAP PLANINDA YOK") | H23: 8000
A24: 8 | B24: 46047 | C24: Alış e-Faturası ÖRN-A-004 | D24: Ocak dükkân kirası (kiraya veren şirket) | E24: 793 | F24: =IFERROR(VLOOKUP(E24,'Hesap Planı'!$A$5:$B$22,2,FALSE),"HESAP PLANINDA YOK") | G24: 25000 | I24: =IF(ROUND(SUMIF($A$5:$A$200,A24,$G$5:$G$200)-SUMIF($A$5:$A$200,A24,$H$5:$H$200),2)=0,"DENK","DENK DEĞİL")
A25: 8 | B25: 46047 | C25: Alış e-Faturası ÖRN-A-004 | D25: Ocak dükkân kirası (kiraya veren şirket) | E25: 191 | F25: =IFERROR(VLOOKUP(E25,'Hesap Planı'!$A$5:$B$22,2,FALSE),"HESAP PLANINDA YOK") | G25: 5000
A26: 8 | B26: 46047 | C26: Alış e-Faturası ÖRN-A-004 | D26: Ocak dükkân kirası (kiraya veren şirket) | E26: 102 | F26: =IFERROR(VLOOKUP(E26,'Hesap Planı'!$A$5:$B$22,2,FALSE),"HESAP PLANINDA YOK") | H26: 30000
A27: 9 | B27: 46050 | C27: Alış e-Faturası ÖRN-A-005 | D27: Elektrik ve internet faturası | E27: 793 | F27: =IFERROR(VLOOKUP(E27,'Hesap Planı'!$A$5:$B$22,2,FALSE),"HESAP PLANINDA YOK") | G27: 4000 | I27: =IF(ROUND(SUMIF($A$5:$A$200,A27,$G$5:$G$200)-SUMIF($A$5:$A$200,A27,$H$5:$H$200),2)=0,"DENK","DENK DEĞİL")
A28: 9 | B28: 46050 | C28: Alış e-Faturası ÖRN-A-005 | D28: Elektrik ve internet faturası | E28: 191 | F28: =IFERROR(VLOOKUP(E28,'Hesap Planı'!$A$5:$B$22,2,FALSE),"HESAP PLANINDA YOK") | G28: 800
A29: 9 | B29: 46050 | C29: Alış e-Faturası ÖRN-A-005 | D29: Elektrik ve internet faturası | E29: 102 | F29: =IFERROR(VLOOKUP(E29,'Hesap Planı'!$A$5:$B$22,2,FALSE),"HESAP PLANINDA YOK") | H29: 4800
A30: 10 | B30: 46052 | C30: Banka dekontu ÖRN-D-003 | D30: Örnek Kafe Ltd.'den tahsilat | E30: 102 | F30: =IFERROR(VLOOKUP(E30,'Hesap Planı'!$A$5:$B$22,2,FALSE),"HESAP PLANINDA YOK") | G30: 48000 | I30: =IF(ROUND(SUMIF($A$5:$A$200,A30,$G$5:$G$200)-SUMIF($A$5:$A$200,A30,$H$5:$H$200),2)=0,"DENK","DENK DEĞİL")
A31: 10 | B31: 46052 | C31: Banka dekontu ÖRN-D-003 | D31: Örnek Kafe Ltd.'den tahsilat | E31: 120 | F31: =IFERROR(VLOOKUP(E31,'Hesap Planı'!$A$5:$B$22,2,FALSE),"HESAP PLANINDA YOK") | H31: 48000
A32: 11 | B32: 46052 | C32: Banka dekontu ÖRN-D-004 | D32: Satıcıya kısmi ödeme | E32: 320 | F32: =IFERROR(VLOOKUP(E32,'Hesap Planı'!$A$5:$B$22,2,FALSE),"HESAP PLANINDA YOK") | G32: 100000 | I32: =IF(ROUND(SUMIF($A$5:$A$200,A32,$G$5:$G$200)-SUMIF($A$5:$A$200,A32,$H$5:$H$200),2)=0,"DENK","DENK DEĞİL")
A33: 11 | B33: 46052 | C33: Banka dekontu ÖRN-D-004 | D33: Satıcıya kısmi ödeme | E33: 102 | F33: =IFERROR(VLOOKUP(E33,'Hesap Planı'!$A$5:$B$22,2,FALSE),"HESAP PLANINDA YOK") | H33: 100000
A34: 12 | B34: 46053 | C34: Amortisman tablosu | D34: Ocak ayı amortisman payı (ara dönem) | E34: 796 | F34: =IFERROR(VLOOKUP(E34,'Hesap Planı'!$A$5:$B$22,2,FALSE),"HESAP PLANINDA YOK") | G34: 1500 | I34: =IF(ROUND(SUMIF($A$5:$A$200,A34,$G$5:$G$200)-SUMIF($A$5:$A$200,A34,$H$5:$H$200),2)=0,"DENK","DENK DEĞİL")
A35: 12 | B35: 46053 | C35: Amortisman tablosu | D35: Ocak ayı amortisman payı (ara dönem) | E35: 257 | F35: =IFERROR(VLOOKUP(E35,'Hesap Planı'!$A$5:$B$22,2,FALSE),"HESAP PLANINDA YOK") | H35: 1500
A36: 13 | B36: 46053 | C36: Sayım listesi | D36: Ay sonu sayım: satılan malın maliyeti | E36: 621 | F36: =IFERROR(VLOOKUP(E36,'Hesap Planı'!$A$5:$B$22,2,FALSE),"HESAP PLANINDA YOK") | G36: 50000 | I36: =IF(ROUND(SUMIF($A$5:$A$200,A36,$G$5:$G$200)-SUMIF($A$5:$A$200,A36,$H$5:$H$200),2)=0,"DENK","DENK DEĞİL")
A37: 13 | B37: 46053 | C37: Sayım listesi | D37: Ay sonu sayım: satılan malın maliyeti | E37: 153 | F37: =IFERROR(VLOOKUP(E37,'Hesap Planı'!$A$5:$B$22,2,FALSE),"HESAP PLANINDA YOK") | H37: 50000
A38: 14 | B38: 46053 | C38: Gider dağıtım notu | D38: Gider çeşitleri gelir tablosu hesabına aktarıldı (7/B) | E38: 632 | F38: =IFERROR(VLOOKUP(E38,'Hesap Planı'!$A$5:$B$22,2,FALSE),"HESAP PLANINDA YOK") | G38: 38500 | I38: =IF(ROUND(SUMIF($A$5:$A$200,A38,$G$5:$G$200)-SUMIF($A$5:$A$200,A38,$H$5:$H$200),2)=0,"DENK","DENK DEĞİL")
A39: 14 | B39: 46053 | C39: Gider dağıtım notu | D39: Gider çeşitleri gelir tablosu hesabına aktarıldı (7/B) | E39: 798 | F39: =IFERROR(VLOOKUP(E39,'Hesap Planı'!$A$5:$B$22,2,FALSE),"HESAP PLANINDA YOK") | H39: 38500
A40: 15 | B40: 46053 | C40: KDV hesap özeti | D40: Ocak KDV mahsubu (kalan indirilecek KDV devreder) | E40: 391 | F40: =IFERROR(VLOOKUP(E40,'Hesap Planı'!$A$5:$B$22,2,FALSE),"HESAP PLANINDA YOK") | G40: 20000 | I40: =IF(ROUND(SUMIF($A$5:$A$200,A40,$G$5:$G$200)-SUMIF($A$5:$A$200,A40,$H$5:$H$200),2)=0,"DENK","DENK DEĞİL")
A41: 15 | B41: 46053 | C41: KDV hesap özeti | D41: Ocak KDV mahsubu (kalan indirilecek KDV devreder) | E41: 191 | F41: =IFERROR(VLOOKUP(E41,'Hesap Planı'!$A$5:$B$22,2,FALSE),"HESAP PLANINDA YOK") | H41: 20000
...

Sheet Büyük Defter
A1: Büyük Defter (Defteri Kebir) — Ocak 2026
A2: Yevmiyedeki her satır kendi hesabına taşınır; bakiye = borç − alacak (artı: borç bakiyesi, eksi: alacak bakiyesi).
A4: 100 · Kasa
A5: Tarih | B5: Madde | C5: Açıklama | D5: Borç | E5: Alacak | F5: Bakiye | G5: Yön
A6: =Yevmiye!B7 | B6: =Yevmiye!A7 | C6: =Yevmiye!D7 | D6: =N(Yevmiye!G7) | E6: =N(Yevmiye!H7) | F6: =0+D6-E6 | G6: =IF(ROUND(F6,2)>0,"Borç",IF(ROUND(F6,2)<0,"Alacak","—"))
A7: =Yevmiye!B14 | B7: =Yevmiye!A14 | C7: =Yevmiye!D14 | D7: =N(Yevmiye!G14) | E7: =N(Yevmiye!H14) | F7: =F6+D7-E7 | G7: =IF(ROUND(F7,2)>0,"Borç",IF(ROUND(F7,2)<0,"Alacak","—"))
C8: Toplam | D8: =SUM(D6:D7) | E8: =SUM(E6:E7) | F8: =D8-E8
A10: 102 · Bankalar
A11: Tarih | B11: Madde | C11: Açıklama | D11: Borç | E11: Alacak | F11: Bakiye | G11: Yön
A12: =Yevmiye!B5 | B12: =Yevmiye!A5 | C12: =Yevmiye!D5 | D12: =N(Yevmiye!G5) | E12: =N(Yevmiye!H5) | F12: =0+D12-E12 | G12: =IF(ROUND(F12,2)>0,"Borç",IF(ROUND(F12,2)<0,"Alacak","—"))
A13: =Yevmiye!B8 | B13: =Yevmiye!A8 | C13: =Yevmiye!D8 | D13: =N(Yevmiye!G8) | E13: =N(Yevmiye!H8) | F13: =F12+D13-E13 | G13: =IF(ROUND(F13,2)>0,"Borç",IF(ROUND(F13,2)<0,"Alacak","—"))
A14: =Yevmiye!B11 | B14: =Yevmiye!A11 | C14: =Yevmiye!D11 | D14: =N(Yevmiye!G11) | E14: =N(Yevmiye!H11) | F14: =F13+D14-E14 | G14: =IF(ROUND(F14,2)>0,"Borç",IF(ROUND(F14,2)<0,"Alacak","—"))
A15: =Yevmiye!B18 | B15: =Yevmiye!A18 | C15: =Yevmiye!D18 | D15: =N(Yevmiye!G18) | E15: =N(Yevmiye!H18) | F15: =F14+D15-E15 | G15: =IF(ROUND(F15,2)>0,"Borç",IF(ROUND(F15,2)<0,"Alacak","—"))
A16: =Yevmiye!B26 | B16: =Yevmiye!A26 | C16: =Yevmiye!D26 | D16: =N(Yevmiye!G26) | E16: =N(Yevmiye!H26) | F16: =F15+D16-E16 | G16: =IF(ROUND(F16,2)>0,"Borç",IF(ROUND(F16,2)<0,"Alacak","—"))
A17: =Yevmiye!B29 | B17: =Yevmiye!A29 | C17: =Yevmiye!D29 | D17: =N(Yevmiye!G29) | E17: =N(Yevmiye!H29) | F17: =F16+D17-E17 | G17: =IF(ROUND(F17,2)>0,"Borç",IF(ROUND(F17,2)<0,"Alacak","—"))
A18: =Yevmiye!B30 | B18: =Yevmiye!A30 | C18: =Yevmiye!D30 | D18: =N(Yevmiye!G30) | E18: =N(Yevmiye!H30) | F18: =F17+D18-E18 | G18: =IF(ROUND(F18,2)>0,"Borç",IF(ROUND(F18,2)<0,"Alacak","—"))
A19: =Yevmiye!B33 | B19: =Yevmiye!A33 | C19: =Yevmiye!D33 | D19: =N(Yevmiye!G33) | E19: =N(Yevmiye!H33) | F19: =F18+D19-E19 | G19: =IF(ROUND(F19,2)>0,"Borç",IF(ROUND(F19,2)<0,"Alacak","—"))
C20: Toplam | D20: =SUM(D12:D19) | E20: =SUM(E12:E19) | F20: =D20-E20
A22: 120 · Alıcılar
A23: Tarih | B23: Madde | C23: Açıklama | D23: Borç | E23: Alacak | F23: Bakiye | G23: Yön
A24: =Yevmiye!B21 | B24: =Yevmiye!A21 | C24: =Yevmiye!D21 | D24: =N(Yevmiye!G21) | E24: =N(Yevmiye!H21) | F24: =0+D24-E24 | G24: =IF(ROUND(F24,2)>0,"Borç",IF(ROUND(F24,2)<0,"Alacak","—"))
A25: =Yevmiye!B31 | B25: =Yevmiye!A31 | C25: =Yevmiye!D31 | D25: =N(Yevmiye!G31) | E25: =N(Yevmiye!H31) | F25: =F24+D25-E25 | G25: =IF(ROUND(F25,2)>0,"Borç",IF(ROUND(F25,2)<0,"Alacak","—"))
C26: Toplam | D26: =SUM(D24:D25) | E26: =SUM(E24:E25) | F26: =D26-E26
A28: 153 · Ticari Mallar
A29: Tarih | B29: Madde | C29: Açıklama | D29: Borç | E29: Alacak | F29: Bakiye | G29: Yön
A30: =Yevmiye!B15 | B30: =Yevmiye!A15 | C30: =Yevmiye!D15 | D30: =N(Yevmiye!G15) | E30: =N(Yevmiye!H15) | F30: =0+D30-E30 | G30: =IF(ROUND(F30,2)>0,"Borç",IF(ROUND(F30,2)<0,"Alacak","—"))
A31: =Yevmiye!B37 | B31: =Yevmiye!A37 | C31: =Yevmiye!D37 | D31: =N(Yevmiye!G37) | E31: =N(Yevmiye!H37) | F31: =F30+D31-E31 | G31: =IF(ROUND(F31,2)>0,"Borç",IF(ROUND(F31,2)<0,"Alacak","—"))
C32: Toplam | D32: =SUM(D30:D31) | E32: =SUM(E30:E31) | F32: =D32-E32
A34: 191 · İndirilecek KDV
A35: Tarih | B35: Madde | C35: Açıklama | D35: Borç | E35: Alacak | F35: Bakiye | G35: Yön
A36: =Yevmiye!B10 | B36: =Yevmiye!A10 | C36: =Yevmiye!D10 | D36: =N(Yevmiye!G10) | E36: =N(Yevmiye!H10) | F36: =0+D36-E36 | G36: =IF(ROUND(F36,2)>0,"Borç",IF(ROUND(F36,2)<0,"Alacak","—"))
A37: =Yevmiye!B13 | B37: =Yevmiye!A13 | C37: =Yevmiye!D13 | D37: =N(Yevmiye!G13) | E37: =N(Yevmiye!H13) | F37: =F36+D37-E37 | G37: =IF(ROUND(F37,2)>0,"Borç",IF(ROUND(F37,2)<0,"Alacak","—"))
A38: =Yevmiye!B16 | B38: =Yevmiye!A16 | C38: =Yevmiye!D16 | D38: =N(Yevmiye!G16) | E38: =N(Yevmiye!H16) | F38: =F37+D38-E38 | G38: =IF(ROUND(F38,2)>0,"Borç",IF(ROUND(F38,2)<0,"Alacak","—"))
A39: =Yevmiye!B25 | B39: =Yevmiye!A25 | C39: =Yevmiye!D25 | D39: =N(Yevmiye!G25) | E39: =N(Yevmiye!H25) | F39: =F38+D39-E39 | G39: =IF(ROUND(F39,2)>0,"Borç",IF(ROUND(F39,2)<0,"Alacak","—"))
A40: =Yevmiye!B28 | B40: =Yevmiye!A28 | C40: =Yevmiye!D28 | D40: =N(Yevmiye!G28) | E40: =N(Yevmiye!H28) | F40: =F39+D40-E40 | G40: =IF(ROUND(F40,2)>0,"Borç",IF(ROUND(F40,2)<0,"Alacak","—"))
A41: =Yevmiye!B41 | B41: =Yevmiye!A41 | C41: =Yevmiye!D41 | D41: =N(Yevmiye!G41) | E41: =N(Yevmiye!H41) | F41: =F40+D41-E41 | G41: =IF(ROUND(F41,2)>0,"Borç",IF(ROUND(F41,2)<0,"Alacak","—"))
C42: Toplam | D42: =SUM(D36:D41) | E42: =SUM(E36:E41) | F42: =D42-E42
A44: 255 · Demirbaşlar
A45: Tarih | B45: Madde | C45: Açıklama | D45: Borç | E45: Alacak | F45: Bakiye | G45: Yön
A46: =Yevmiye!B9 | B46: =Yevmiye!A9 | C46: =Yevmiye!D9 | D46: =N(Yevmiye!G9) | E46: =N(Yevmiye!H9) | F46: =0+D46-E46 | G46: =IF(ROUND(F46,2)>0,"Borç",IF(ROUND(F46,2)<0,"Alacak","—"))
...

Sheet Mizan
A1: Mizan — 31.01.2026
A2: Toplamlar Yevmiye sayfasından SUMIF ile gelir. Borç toplamı = alacak toplamı ve borç kalanı = alacak kalanı olmalıdır.
A4: Kod | B4: Hesap adı | C4: Borç toplamı | D4: Alacak toplamı | E4: Borç kalanı | F4: Alacak kalanı
A5: 100 | B5: Kasa | C5: =SUMIF(Yevmiye!$E$5:$E$200,A5,Yevmiye!$G$5:$G$200) | D5: =SUMIF(Yevmiye!$E$5:$E$200,A5,Yevmiye!$H$5:$H$200) | E5: =MAX(C5-D5,0) | F5: =MAX(D5-C5,0)
A6: 102 | B6: Bankalar | C6: =SUMIF(Yevmiye!$E$5:$E$200,A6,Yevmiye!$G$5:$G$200) | D6: =SUMIF(Yevmiye!$E$5:$E$200,A6,Yevmiye!$H$5:$H$200) | E6: =MAX(C6-D6,0) | F6: =MAX(D6-C6,0)
A7: 120 | B7: Alıcılar | C7: =SUMIF(Yevmiye!$E$5:$E$200,A7,Yevmiye!$G$5:$G$200) | D7: =SUMIF(Yevmiye!$E$5:$E$200,A7,Yevmiye!$H$5:$H$200) | E7: =MAX(C7-D7,0) | F7: =MAX(D7-C7,0)
A8: 153 | B8: Ticari Mallar | C8: =SUMIF(Yevmiye!$E$5:$E$200,A8,Yevmiye!$G$5:$G$200) | D8: =SUMIF(Yevmiye!$E$5:$E$200,A8,Yevmiye!$H$5:$H$200) | E8: =MAX(C8-D8,0) | F8: =MAX(D8-C8,0)
A9: 191 | B9: İndirilecek KDV | C9: =SUMIF(Yevmiye!$E$5:$E$200,A9,Yevmiye!$G$5:$G$200) | D9: =SUMIF(Yevmiye!$E$5:$E$200,A9,Yevmiye!$H$5:$H$200) | E9: =MAX(C9-D9,0) | F9: =MAX(D9-C9,0)
A10: 255 | B10: Demirbaşlar | C10: =SUMIF(Yevmiye!$E$5:$E$200,A10,Yevmiye!$G$5:$G$200) | D10: =SUMIF(Yevmiye!$E$5:$E$200,A10,Yevmiye!$H$5:$H$200) | E10: =MAX(C10-D10,0) | F10: =MAX(D10-C10,0)
A11: 257 | B11: Birikmiş Amortismanlar (-) | C11: =SUMIF(Yevmiye!$E$5:$E$200,A11,Yevmiye!$G$5:$G$200) | D11: =SUMIF(Yevmiye!$E$5:$E$200,A11,Yevmiye!$H$5:$H$200) | E11: =MAX(C11-D11,0) | F11: =MAX(D11-C11,0)
A12: 320 | B12: Satıcılar | C12: =SUMIF(Yevmiye!$E$5:$E$200,A12,Yevmiye!$G$5:$G$200) | D12: =SUMIF(Yevmiye!$E$5:$E$200,A12,Yevmiye!$H$5:$H$200) | E12: =MAX(C12-D12,0) | F12: =MAX(D12-C12,0)
A13: 360 | B13: Ödenecek Vergi ve Fonlar | C13: =SUMIF(Yevmiye!$E$5:$E$200,A13,Yevmiye!$G$5:$G$200) | D13: =SUMIF(Yevmiye!$E$5:$E$200,A13,Yevmiye!$H$5:$H$200) | E13: =MAX(C13-D13,0) | F13: =MAX(D13-C13,0)
A14: 391 | B14: Hesaplanan KDV | C14: =SUMIF(Yevmiye!$E$5:$E$200,A14,Yevmiye!$G$5:$G$200) | D14: =SUMIF(Yevmiye!$E$5:$E$200,A14,Yevmiye!$H$5:$H$200) | E14: =MAX(C14-D14,0) | F14: =MAX(D14-C14,0)
A15: 500 | B15: Sermaye | C15: =SUMIF(Yevmiye!$E$5:$E$200,A15,Yevmiye!$G$5:$G$200) | D15: =SUMIF(Yevmiye!$E$5:$E$200,A15,Yevmiye!$H$5:$H$200) | E15: =MAX(C15-D15,0) | F15: =MAX(D15-C15,0)
A16: 600 | B16: Yurt İçi Satışlar | C16: =SUMIF(Yevmiye!$E$5:$E$200,A16,Yevmiye!$G$5:$G$200) | D16: =SUMIF(Yevmiye!$E$5:$E$200,A16,Yevmiye!$H$5:$H$200) | E16: =MAX(C16-D16,0) | F16: =MAX(D16-C16,0)
... A22: 798 | B22: Gider Çeşitleri Yansıtma Hesabı | C22: =SUMIF(Yevmiye!$E$5:$E$200,A22,Yevmiye!$G$5:$G$200) | D22: =SUMIF(Yevmiye!$E$5:$E$200,A22,Yevmiye!$H$5:$H$200) | E22: =MAX(C22-D22,0) | F22: =MAX(D22-C22,0)
B23: TOPLAM | C23: =SUM(C5:C22) | D23: =SUM(D5:D22) | E23: =SUM(E5:E22) | F23: =SUM(F5:F22)
A25: Kontroller
A26: Hareket toplamları (borç = alacak) | E26: =IF(ROUND(C23-D23,2)=0,"DENK","DENK DEĞİL")
A27: Kalan toplamları (borç kalanı = alacak kalanı) | E27: =IF(ROUND(E23-F23,2)=0,"DENK","DENK DEĞİL")
A28: Mizan borç toplamı = Yevmiye borç toplamı | E28: =IF(ROUND(C23-Yevmiye!G201,2)=0,"EŞİT","EŞİT DEĞİL — hesap planında olmayan kod var mı?")
A29: 7/B gider çeşitleri aktarıldı mı (79x − 798 = 0) | E29: =IF(ROUND(SUMIF(A5:A22,">=790",E5:E22)-SUMIF(A5:A22,">=790",F5:F22),2)=0,"AKTARILDI","AKTARILMADI")

Sheet Banka Ekstresi
A1: Banka Ekstresi — Örnek Bank (KURGUSAL) · Ocak 2026
A2: Bankanın gönderdiği belge (dış belge): tutarlar elle yazılıdır, defterden formülle gelmez. Mutabakat: ekstre bakiyesi = defterdeki 102 bakiyesi mi?
A4: Tarih | B4: Açıklama (bankanın yazdığı) | C4: Giren | D4: Çıkan | E4: Bakiye
A5: 46024 | B5: Ortakların sermaye ödemesi bankaya yatırıldı | C5: 300000 | E5: =0+N(C5)-N(D5)
A6: 46025 | B6: Bankadan kasaya para çekildi | D6: 20000 | E6: =E5+N(C6)-N(D6)
A7: 46028 | B7: Tezgâh ve raf sistemi alındı (demirbaş) | D7: 108000 | E7: =E6+N(C7)-N(D7)
A8: 46037 | B8: Bireysel müşterilere satışlar (kartla tahsil) | C8: 72000 | E8: =E7+N(C8)-N(D8)
A9: 46047 | B9: Ocak dükkân kirası (kiraya veren şirket) | D9: 30000 | E9: =E8+N(C9)-N(D9)
A10: 46050 | B10: Elektrik ve internet faturası | D10: 4800 | E10: =E9+N(C10)-N(D10)
A11: 46052 | B11: Örnek Kafe Ltd.'den tahsilat | C11: 48000 | E11: =E10+N(C11)-N(D11)
A12: 46052 | B12: Satıcıya kısmi ödeme | D12: 100000 | E12: =E11+N(C12)-N(D12)
A13: 46053 | B13: Hesap işletim ücreti | D13: 50 | E13: =E12+N(C13)-N(D13)
A15: Mutabakat
B16: Ekstre bakiyesi (31.01.2026) | E16: =E13
B17: Defterdeki 102 Bankalar bakiyesi (Mizan) | E17: =SUMIF(Mizan!$A$5:$A$40,102,Mizan!$E$5:$E$40)
B18: Fark (ekstre − defter) | E18: =E16-E17
B19: Farkın nedeni: bankanın kestiği ücret deftere henüz işlenmedi (Ders 2.3 görevi). Hangi hesaba yazılacağını mali müşavirinle netleştir.

Sheet KDV
A1: KDV — Ocak 2026
A2: Oran Bilgi!B15'ten okunur (genel oran, kaynaklı). Hesaplanan KDV satışta 391'e, indirilecek KDV alışta 191'e yazılır.
A4: Madde | B4: Belge | C4: Tür | D4: Matrah | E4: Oran | F4: KDV (hesap) | G4: Deftere yazılan | H4: Kontrol
A5: 3 | B5: Alış e-Faturası ÖRN-A-001 | C5: Alış | D5: 90000 | E5: =Bilgi!$B$15 | F5: =ROUND(D5*E5,2) | G5: =SUMIFS(Yevmiye!$G$5:$G$200,Yevmiye!$A$5:$A$200,A5,Yevmiye!$E$5:$E$200,191) | H5: =IF(ROUND(F5-G5,2)=0,"TUTUYOR","FARK VAR")
A6: 4 | B6: Alış faturası ÖRN-A-002 | C6: Alış | D6: 8000 | E6: =Bilgi!$B$15 | F6: =ROUND(D6*E6,2) | G6: =SUMIFS(Yevmiye!$G$5:$G$200,Yevmiye!$A$5:$A$200,A6,Yevmiye!$E$5:$E$200,191) | H6: =IF(ROUND(F6-G6,2)=0,"TUTUYOR","FARK VAR")
A7: 5 | B7: Alış e-Faturası ÖRN-A-003 | C7: Alış | D7: 150000 | E7: =Bilgi!$B$15 | F7: =ROUND(D7*E7,2) | G7: =SUMIFS(Yevmiye!$G$5:$G$200,Yevmiye!$A$5:$A$200,A7,Yevmiye!$E$5:$E$200,191) | H7: =IF(ROUND(F7-G7,2)=0,"TUTUYOR","FARK VAR")
A8: 6 | B8: e-Arşiv faturalar ÖRN-S-001…040 | C8: Satış | D8: 60000 | E8: =Bilgi!$B$15 | F8: =ROUND(D8*E8,2) | G8: =SUMIFS(Yevmiye!$H$5:$H$200,Yevmiye!$A$5:$A$200,A8,Yevmiye!$E$5:$E$200,391) | H8: =IF(ROUND(F8-G8,2)=0,"TUTUYOR","FARK VAR")
A9: 7 | B9: Satış e-Faturası ÖRN-S-041 | C9: Satış | D9: 40000 | E9: =Bilgi!$B$15 | F9: =ROUND(D9*E9,2) | G9: =SUMIFS(Yevmiye!$H$5:$H$200,Yevmiye!$A$5:$A$200,A9,Yevmiye!$E$5:$E$200,391) | H9: =IF(ROUND(F9-G9,2)=0,"TUTUYOR","FARK VAR")
A10: 8 | B10: Alış e-Faturası ÖRN-A-004 | C10: Alış | D10: 25000 | E10: =Bilgi!$B$15 | F10: =ROUND(D10*E10,2) | G10: =SUMIFS(Yevmiye!$G$5:$G$200,Yevmiye!$A$5:$A$200,A10,Yevmiye!$E$5:$E$200,191) | H10: =IF(ROUND(F10-G10,2)=0,"TUTUYOR","FARK VAR")
A11: 9 | B11: Alış e-Faturası ÖRN-A-005 | C11: Alış | D11: 4000 | E11: =Bilgi!$B$15 | F11: =ROUND(D11*E11,2) | G11: =SUMIFS(Yevmiye!$G$5:$G$200,Yevmiye!$A$5:$A$200,A11,Yevmiye!$E$5:$E$200,191) | H11: =IF(ROUND(F11-G11,2)=0,"TUTUYOR","FARK VAR")
A13: Dönem özeti
B14: Hesaplanan KDV (satışlar) | D14: =SUMIF(C5:C11,"Satış",F5:F11)
B15: İndirilecek KDV (alışlar) | D15: =SUMIF(C5:C11,"Alış",F5:F11)
B16: Önceki dönemden devreden KDV | D16: 0
B17: Ödenecek KDV | D17: =MAX(D14-D15-D16,0)
B18: Sonraki döneme devreden KDV | D18: =MAX(D15+D16-D14,0)
B19: Kontrol: devreden = 191 hesabının ay sonu borç kalanı | D19: =IF(ROUND(D18-SUMIF(Mizan!A5:A40,191,Mizan!E5:E40),2)=0,"TUTUYOR","FARK VAR")
A21: ÖRNEK ay — rakamlar uydurmadır (devreden KDV'nin nasıl kullanıldığını görmek için)
B22: Satış matrahı (ÖRNEK) | D22: 300000
B23: Alış matrahı (ÖRNEK) | D23: 120000
B24: Hesaplanan KDV | D24: =ROUND(D22*Bilgi!$B$15,2)
B25: İndirilecek KDV | D25: =ROUND(D23*Bilgi!$B$15,2)
B26: Önceki dönemden devreden (Ocak'tan) | D26: =D18
B27: Ödenecek KDV | D27: =MAX(D24-D25-D26,0)
B28: Sonraki döneme devreden | D28: =MAX(D25+D26-D24,0)
A30: KDV dahil tutardan matrahı bulmak
B31: KDV dahil tutar (ÖRNEK) | D31: 1200
B32: Matrah = dahil tutar / (1 + oran) | D32: =ROUND(D31/(1+Bilgi!$B$15),2)
B33: KDV = dahil tutar − matrah | D33: =D31-D32
A35: Beyan ve ödeme tarihleri kanunda değil, GİB vergi takviminde güncel hâliyle görülür (ör. Ağustos 2026 dönemi: son gün 28.09.2026).

Sheet Stok
A1: Stok ve Satılan Malın Maliyeti — Ocak 2026
A2: Aralıklı envanter: ay sonunda sayılır; SMM = dönem başı stok + dönem içi alışlar − dönem sonu stok.
A4: Ürün (ay sonu sayım) | B4: Birim | C4: Miktar | D4: Birim maliyet | E4: Tutar
A5: French press (1 lt) | B5: adet | C5: 40 | D5: 750 | E5: =C5*D5
A6: Dökme demleme seti | B6: adet | C6: 50 | D6: 600 | E6: =C6*D6
A7: El değirmeni | B7: adet | C7: 20 | D7: 1500 | E7: =C7*D7
A8: Filtre kâğıdı (100'lü) | B8: paket | C8: 200 | D8: 50 | E8: =C8*D8
A9: Dönem sonu stok (sayım toplamı) | E9: =SUM(E5:E8)
A11: SMM hesabı
A12: Dönem başı stok | E12: 0
A13: + Dönem içi alışlar (153 borç, sayım kaydı hariç) | E13: =SUMIFS(Yevmiye!$G$5:$G$200,Yevmiye!$E$5:$E$200,153,Yevmiye!$A$5:$A$200,"<>13")
A14: − Dönem sonu stok (sayım) | E14: =E9
A15: Satılan malın maliyeti (SMM) | E15: =E12+E13-E14
A16: Kontrol: SMM = yevmiyedeki 621 kaydı | E16: =IF(ROUND(E15-SUMIF(Yevmiye!$E$5:$E$200,621,Yevmiye!$G$5:$G$200),2)=0,"TUTUYOR","FARK VAR")
A17: Kontrol: sayım = 153 hesabının ay sonu kalanı | E17: =IF(ROUND(E9-SUMIF(Mizan!A5:A40,153,Mizan!E5:E40),2)=0,"TUTUYOR","FARK VAR")

Sheet Amortisman
A1: Amortisman — Tezgâh ve raf sistemi
A2: VUK md. 313–320: normal amortisman oranı = 1 / faydalı ömür; azalan bakiyeler oranı normalin iki katı, en çok %50 (VUK mük. md. 315).
A4: Kıymet | B4: Tezgâh ve raf sistemi (demirbaş, 255)
A5: Maliyet bedeli (255 borç) | B5: =SUMIF(Yevmiye!$E$5:$E$200,255,Yevmiye!$G$5:$G$200)
A6: Aktife giriş | B6: 46028
A7: Faydalı ömür (yıl) — ÖRNEK | B7: =Bilgi!$B$17
A8: Normal amortisman oranı | B8: =1/B7
A9: Azalan bakiyeler oranı | B9: =MIN(2*B8,0.5)
A11: Yıl | B11: Normal: amortisman | C11: Normal: birikmiş | D11: Normal: net değer | E11: Azalan: dönem başı | F11: Azalan: amortisman | G11: Azalan: net değer
A12: 2026 | B12: =IF(A12-$A$12<$B$7,ROUND($B$5*$B$8,2),0) | C12: =SUM($B$12:B12) | D12: =$B$5-C12 | E12: =$B$5 | F12: =IF(A12-$A$12=$B$7-1,E12,ROUND(E12*$B$9,2)) | G12: =E12-F12
A13: 2027 | B13: =IF(A13-$A$12<$B$7,ROUND($B$5*$B$8,2),0) | C13: =SUM($B$12:B13) | D13: =$B$5-C13 | E13: =G12 | F13: =IF(A13-$A$12=$B$7-1,E13,ROUND(E13*$B$9,2)) | G13: =E13-F13
A14: 2028 | B14: =IF(A14-$A$12<$B$7,ROUND($B$5*$B$8,2),0) | C14: =SUM($B$12:B14) | D14: =$B$5-C14 | E14: =G13 | F14: =IF(A14-$A$12=$B$7-1,E14,ROUND(E14*$B$9,2)) | G14: =E14-F14
A15: 2029 | B15: =IF(A15-$A$12<$B$7,ROUND($B$5*$B$8,2),0) | C15: =SUM($B$12:B15) | D15: =$B$5-C15 | E15: =G14 | F15: =IF(A15-$A$12=$B$7-1,E15,ROUND(E15*$B$9,2)) | G15: =E15-F15
A16: 2030 | B16: =IF(A16-$A$12<$B$7,ROUND($B$5*$B$8,2),0) | C16: =SUM($B$12:B16) | D16: =$B$5-C16 | E16: =G15 | F16: =IF(A16-$A$12=$B$7-1,E16,ROUND(E16*$B$9,2)) | G16: =E16-F16
A17: Toplam | B17: =SUM(B12:B16) | F17: =SUM(F12:F16)
A18: Kontrol: her iki yöntemde toplam = maliyet | B18: =IF(AND(ROUND(B17-B5,2)=0,ROUND(F17-B5,2)=0),"TUTUYOR","FARK VAR")
A20: Ocak payı (ara dönem, yıllık / 12) | B20: =ROUND(B12/12,2)
A21: Kontrol: yevmiyedeki 796 kaydı | B21: =IF(ROUND(B20-SUMIF(Yevmiye!$E$5:$E$200,796,Yevmiye!$G$5:$G$200),2)=0,"TUTUYOR","FARK VAR")
A22: Not: vergi hesabında amortisman yıllık ayrılır (VUK md. 320); aylık pay yalnız ara dönem yönetim tablosu içindir.
A24: Doğrudan gider mi, amortisman mı? (VUK md. 313 — 2026 haddi Bilgi!B16)
A25: Kıymet | B25: Değer | C25: Sonuç
A26: Barkod okuyucu | B26: 8000 | C26: =IF(B26<=Bilgi!$B$16,"doğrudan gider yazılabilir","amortismana tabi")
A27: Tezgâh ve raf sistemi | B27: =B5 | C27: =IF(B27<=Bilgi!$B$16,"doğrudan gider yazılabilir","amortismana tabi")

Sheet Gelir Tablosu
A1: Gelir Tablosu — 01.01.2026–31.01.2026 (ara dönem)
A2: Tutarlar Mizan sayfasından formülle gelir. Vergi karşılığı bu çalışmanın kapsamı dışında (vergi öncesi kâr).
A4: A. Brüt satışlar — Yurt içi satışlar (600) | B4: =SUMIF(Mizan!$A$5:$A$40,600,Mizan!$F$5:$F$40)-SUMIF(Mizan!$A$5:$A$40,600,Mizan!$E$5:$E$40)
A5: B. Satış indirimleri (−) | B5: 0
A6: C. Net satışlar | B6: =B4-B5
A7: D. Satışların maliyeti (−) — Satılan ticari mallar maliyeti (621) | B7: =SUMIF(Mizan!$A$5:$A$40,621,Mizan!$E$5:$E$40)-SUMIF(Mizan!$A$5:$A$40,621,Mizan!$F$5:$F$40)
A8: Brüt satış kârı | B8: =B6-B7
A9: E. Faaliyet giderleri (−) — Genel yönetim giderleri (632) | B9: =SUMIF(Mizan!$A$5:$A$40,632,Mizan!$E$5:$E$40)-SUMIF(Mizan!$A$5:$A$40,632,Mizan!$F$5:$F$40)
A10: Faaliyet kârı | B10: =B8-B9
A11: Dönem kârı (vergi öncesi) | B11: =B10
A13: Brüt kâr marjı | B13: =IF(B6=0,0,B8/B6)
A15: Kontrol: gelir tablosu hesaplarının net kalanı = dönem kârı | B15: =IF(ROUND(SUMIFS(Mizan!$F$5:$F$40,Mizan!$A$5:$A$40,">=600",Mizan!$A$5:$A$40,"<700")-SUMIFS(Mizan!$E$5:$E$40,Mizan!$A$5:$A$40,">=600",Mizan!$A$5:$A$40,"<700")-B11,2)=0,"TUTUYOR","FARK VAR")

Sheet Bilanço
A1: Bilanço — 31.01.2026 (ara dönem)
A2: Aktif (varlıklar) = Pasif (kaynaklar). Dönem kârı Gelir Tablosu'ndan gelir; resmî yıl sonu bilançosu değildir.
A4: AKTİF (Varlıklar) | B4: Tutar | D4: PASİF (Kaynaklar) | E4: Tutar
A5: I. DÖNEN VARLIKLAR | D5: III. KISA VADELİ YABANCI KAYNAKLAR
A6: Kasa (100) | B6: =(SUMIF(Mizan!$A$5:$A$40,100,Mizan!$E$5:$E$40)-SUMIF(Mizan!$A$5:$A$40,100,Mizan!$F$5:$F$40)) | D6: Satıcılar (320) | E6: =(SUMIF(Mizan!$A$5:$A$40,320,Mizan!$F$5:$F$40)-SUMIF(Mizan!$A$5:$A$40,320,Mizan!$E$5:$E$40))
A7: Bankalar (102) | B7: =(SUMIF(Mizan!$A$5:$A$40,102,Mizan!$E$5:$E$40)-SUMIF(Mizan!$A$5:$A$40,102,Mizan!$F$5:$F$40)) | D7: Ödenecek vergi ve fonlar (360) | E7: =(SUMIF(Mizan!$A$5:$A$40,360,Mizan!$F$5:$F$40)-SUMIF(Mizan!$A$5:$A$40,360,Mizan!$E$5:$E$40))
A8: Alıcılar (120) | B8: =(SUMIF(Mizan!$A$5:$A$40,120,Mizan!$E$5:$E$40)-SUMIF(Mizan!$A$5:$A$40,120,Mizan!$F$5:$F$40)) | D8: Hesaplanan KDV (391) | E8: =(SUMIF(Mizan!$A$5:$A$40,391,Mizan!$F$5:$F$40)-SUMIF(Mizan!$A$5:$A$40,391,Mizan!$E$5:$E$40))
A9: Ticari mallar (153) | B9: =(SUMIF(Mizan!$A$5:$A$40,153,Mizan!$E$5:$E$40)-SUMIF(Mizan!$A$5:$A$40,153,Mizan!$F$5:$F$40)) | D9: Kısa vadeli yabancı kaynaklar toplamı | E9: =SUM(E6:E8)
A10: İndirilecek KDV — devreden (191) | B10: =(SUMIF(Mizan!$A$5:$A$40,191,Mizan!$E$5:$E$40)-SUMIF(Mizan!$A$5:$A$40,191,Mizan!$F$5:$F$40)) | D10: V. ÖZ KAYNAKLAR
A11: Dönen varlıklar toplamı | B11: =SUM(B6:B10) | D11: Sermaye (500) | E11: =(SUMIF(Mizan!$A$5:$A$40,500,Mizan!$F$5:$F$40)-SUMIF(Mizan!$A$5:$A$40,500,Mizan!$E$5:$E$40))
A12: II. DURAN VARLIKLAR | D12: Dönem kârı (Gelir Tablosu, vergi öncesi) | E12: ='Gelir Tablosu'!B11
A13: Demirbaşlar (255) | B13: =(SUMIF(Mizan!$A$5:$A$40,255,Mizan!$E$5:$E$40)-SUMIF(Mizan!$A$5:$A$40,255,Mizan!$F$5:$F$40)) | D13: Öz kaynaklar toplamı | E13: =SUM(E11:E12)
A14: Birikmiş amortismanlar (257) (−) | B14: =-(SUMIF(Mizan!$A$5:$A$40,257,Mizan!$F$5:$F$40)-SUMIF(Mizan!$A$5:$A$40,257,Mizan!$E$5:$E$40))
A15: Duran varlıklar toplamı | B15: =SUM(B13:B14)
A17: AKTİF TOPLAMI | B17: =B11+B15 | D17: PASİF TOPLAMI | E17: =E9+E13
A19: Kontrol: aktif = pasif | B19: =IF(ROUND(B17-E17,2)=0,"DENK","DENK DEĞİL")

Sheet Takvim
A1: Vergi Takvimi Örnekleri — 2026
A2: Kaynak: GİB 2026 yıllık vergi takvimi ve gib.gov.tr vergi takvimi sayfası (okundu 2026-09-25). Kendi yükümlülüklerin için güncel takvime ve mali müşavirine bak.
A4: Dönem | B4: Yükümlülük | C4: Son gün | D4: Not
A5: Ocak 2026 | B5: KDV beyanı ve ödemesi | C5: 46083 | D5: Kahve Durağı'nın Ocak beyanı; 28 Şubat Cumartesi → ilk iş günü
A6: Ocak 2026 | B6: Muhtasar ve prim hizmet beyannamesi | C6: 46079 | D6: çalışanı ya da stopaj kesintisi olan işletmeler
A7: Şubat 2026 | B7: KDV beyanı ve ödemesi | C7: 46111 | D7: 28 Mart Cumartesi → 30 Mart Pazartesi
A8: 2025 yılı | B8: Yıllık gelir vergisi beyanı ve 1. taksit | C8: 46112 | D8: şahıs işletmeleri (gelir vergisi mükellefleri)
A9: 2025 yılı | B9: Kurumlar vergisi beyanı ve ödemesi | C9: 46142 | D9: şirketler (Kahve Durağı Ltd. Şti. gibi)
A10: 2026 I. dönem (Ocak–Mart) | B10: Geçici vergi beyanı ve ödemesi | C10: 46160 | D10: 17 Mayıs Pazar → 18 Mayıs
A11: Ağustos 2026 | B11: KDV beyanı ve ödemesi | C11: 46293 | D11: gib.gov.tr vergi takvimi sayfası, 2026-09-25
A12: Ağustos 2026 | B12: Muhtasar ve prim hizmet beyannamesi | C12: 46293 | D12: 26 Eylül Cumartesi → 28 Eylül Pazartesi
A14: Kanun metnindeki gün ile takvimdeki gün aynı olmayabilir: KDV Kanunu md. 41 ve 46 beyan için 24., ödeme için 26. günü yazar;
A15: 2026 takviminde KDV son günü 28'idir (hafta sonuna denk gelirse ilk iş günü). Her zaman güncel GİB takvimine bak.
